Connected!
Setting status to '!help | In 95 servers'
Ignoring exception in on_message
Traceback (most recent call last):
  File "/home/bobwithacamera/.local/lib/python3.5/site-packages/discord/client.py", line 270, in _run_event
    await coro(*args, **kwargs)
  File "bot.py", line 207, in on_message
    user_r = reddit.redditor(user_info['reddit name'])  # makes user
KeyError: 'reddit name'
Connected!
Setting status to '!help | In 95 servers'
Setting status to 'thanks for 90+ servers'
Connected!
Setting status to '!help | In 95 servers'
Setting status to 'thanks for 90+ servers'
Connected!
Setting status to '!help | In 95 servers'
