Traceback (most recent call last):
  File "/home/bobwithacamera/.local/lib/python3.5/site-packages/discord/http.py", line 258, in static_login
    data = await self.request(Route('GET', '/users/@me'))
  File "/home/bobwithacamera/.local/lib/python3.5/site-packages/discord/http.py", line 222, in request
    raise HTTPException(r, data)
discord.errors.HTTPException: 401 UNAUTHORIZED (error code: 0): 401: Unauthorized

The above exception was the direct cause of the following exception:

Traceback (most recent call last):
  File "bot.py", line 279, in <module>
    client.run("")
  File "/home/bobwithacamera/.local/lib/python3.5/site-packages/discord/client.py", line 598, in run
    return future.result()
  File "/usr/lib/python3.5/asyncio/futures.py", line 293, in result
    raise self._exception
  File "/usr/lib/python3.5/asyncio/tasks.py", line 239, in _step
    result = coro.send(None)
  File "/home/bobwithacamera/.local/lib/python3.5/site-packages/discord/client.py", line 579, in runner
    await self.start(*args, **kwargs)
  File "/home/bobwithacamera/.local/lib/python3.5/site-packages/discord/client.py", line 542, in start
    await self.login(*args, bot=bot)
  File "/home/bobwithacamera/.local/lib/python3.5/site-packages/discord/client.py", line 400, in login
    await self.http.static_login(token, bot=bot)
  File "/home/bobwithacamera/.local/lib/python3.5/site-packages/discord/http.py", line 262, in static_login
    raise LoginFailure('Improper token has been passed.') from exc
discord.errors.LoginFailure: Improper token has been passed.
