Connected!
Setting status to '!help | In 82 servers'
Ignoring exception in on_message
Traceback (most recent call last):
  File "bot.py", line 196, in on_message
    with open("users/" + user_id + '.json') as user_data:
FileNotFoundError: [Errno 2] No such file or directory: 'users/473127575426695168.json'

During handling of the above exception, another exception occurred:

Traceback (most recent call last):
  File "/home/bobwithacamera/.local/lib/python3.5/site-packages/discord/client.py", line 270, in _run_event
    await coro(*args, **kwargs)
  File "bot.py", line 227, in on_message
    await loadingMessage.edit(message.author.mention + ' No connected account')
TypeError: edit() takes 1 positional argument but 2 were given
Ignoring exception in on_message
Traceback (most recent call last):
  File "/home/bobwithacamera/.local/lib/python3.5/site-packages/discord/client.py", line 270, in _run_event
    await coro(*args, **kwargs)
  File "bot.py", line 58, in on_message
    await message.author.send(embed=help)
  File "/home/bobwithacamera/.local/lib/python3.5/site-packages/discord/abc.py", line 823, in send
    data = await state.http.send_message(channel.id, content, tts=tts, embed=embed, nonce=nonce)
  File "/home/bobwithacamera/.local/lib/python3.5/site-packages/discord/http.py", line 218, in request
    raise Forbidden(r, data)
discord.errors.Forbidden: 403 FORBIDDEN (error code: 50007): Cannot send messages to this user
Ignoring exception in on_message
Traceback (most recent call last):
  File "/home/bobwithacamera/.local/lib/python3.5/site-packages/discord/client.py", line 270, in _run_event
    await coro(*args, **kwargs)
  File "bot.py", line 58, in on_message
    await message.author.send(embed=help)
  File "/home/bobwithacamera/.local/lib/python3.5/site-packages/discord/abc.py", line 823, in send
    data = await state.http.send_message(channel.id, content, tts=tts, embed=embed, nonce=nonce)
  File "/home/bobwithacamera/.local/lib/python3.5/site-packages/discord/http.py", line 218, in request
    raise Forbidden(r, data)
discord.errors.Forbidden: 403 FORBIDDEN (error code: 50007): Cannot send messages to this user
Ignoring exception in on_message
Traceback (most recent call last):
  File "/home/bobwithacamera/.local/lib/python3.5/site-packages/discord/client.py", line 270, in _run_event
    await coro(*args, **kwargs)
  File "bot.py", line 58, in on_message
    await message.author.send(embed=help)
  File "/home/bobwithacamera/.local/lib/python3.5/site-packages/discord/abc.py", line 823, in send
    data = await state.http.send_message(channel.id, content, tts=tts, embed=embed, nonce=nonce)
  File "/home/bobwithacamera/.local/lib/python3.5/site-packages/discord/http.py", line 218, in request
    raise Forbidden(r, data)
discord.errors.Forbidden: 403 FORBIDDEN (error code: 50007): Cannot send messages to this user
Ignoring exception in on_message
Traceback (most recent call last):
  File "/home/bobwithacamera/.local/lib/python3.5/site-packages/discord/client.py", line 270, in _run_event
    await coro(*args, **kwargs)
  File "bot.py", line 58, in on_message
    await message.author.send(embed=help)
  File "/home/bobwithacamera/.local/lib/python3.5/site-packages/discord/abc.py", line 823, in send
    data = await state.http.send_message(channel.id, content, tts=tts, embed=embed, nonce=nonce)
  File "/home/bobwithacamera/.local/lib/python3.5/site-packages/discord/http.py", line 218, in request
    raise Forbidden(r, data)
discord.errors.Forbidden: 403 FORBIDDEN (error code: 50007): Cannot send messages to this user
Ignoring exception in on_message
Traceback (most recent call last):
  File "/home/bobwithacamera/.local/lib/python3.5/site-packages/discord/client.py", line 270, in _run_event
    await coro(*args, **kwargs)
  File "bot.py", line 58, in on_message
    await message.author.send(embed=help)
  File "/home/bobwithacamera/.local/lib/python3.5/site-packages/discord/abc.py", line 823, in send
    data = await state.http.send_message(channel.id, content, tts=tts, embed=embed, nonce=nonce)
  File "/home/bobwithacamera/.local/lib/python3.5/site-packages/discord/http.py", line 218, in request
    raise Forbidden(r, data)
discord.errors.Forbidden: 403 FORBIDDEN (error code: 50007): Cannot send messages to this user
Ignoring exception in on_message
Traceback (most recent call last):
  File "/home/bobwithacamera/.local/lib/python3.5/site-packages/discord/client.py", line 270, in _run_event
    await coro(*args, **kwargs)
  File "bot.py", line 58, in on_message
    await message.author.send(embed=help)
  File "/home/bobwithacamera/.local/lib/python3.5/site-packages/discord/abc.py", line 823, in send
    data = await state.http.send_message(channel.id, content, tts=tts, embed=embed, nonce=nonce)
  File "/home/bobwithacamera/.local/lib/python3.5/site-packages/discord/http.py", line 218, in request
    raise Forbidden(r, data)
discord.errors.Forbidden: 403 FORBIDDEN (error code: 50007): Cannot send messages to this user
Ignoring exception in on_message
Traceback (most recent call last):
  File "/home/bobwithacamera/.local/lib/python3.5/site-packages/discord/client.py", line 270, in _run_event
    await coro(*args, **kwargs)
  File "bot.py", line 58, in on_message
    await message.author.send(embed=help)
  File "/home/bobwithacamera/.local/lib/python3.5/site-packages/discord/abc.py", line 823, in send
    data = await state.http.send_message(channel.id, content, tts=tts, embed=embed, nonce=nonce)
  File "/home/bobwithacamera/.local/lib/python3.5/site-packages/discord/http.py", line 218, in request
    raise Forbidden(r, data)
discord.errors.Forbidden: 403 FORBIDDEN (error code: 50007): Cannot send messages to this user
Ignoring exception in on_message
Traceback (most recent call last):
  File "/home/bobwithacamera/.local/lib/python3.5/site-packages/discord/client.py", line 270, in _run_event
    await coro(*args, **kwargs)
  File "bot.py", line 58, in on_message
    await message.author.send(embed=help)
  File "/home/bobwithacamera/.local/lib/python3.5/site-packages/discord/abc.py", line 823, in send
    data = await state.http.send_message(channel.id, content, tts=tts, embed=embed, nonce=nonce)
  File "/home/bobwithacamera/.local/lib/python3.5/site-packages/discord/http.py", line 218, in request
    raise Forbidden(r, data)
discord.errors.Forbidden: 403 FORBIDDEN (error code: 50007): Cannot send messages to this user
Ignoring exception in on_message
Traceback (most recent call last):
  File "/home/bobwithacamera/.local/lib/python3.5/site-packages/discord/client.py", line 270, in _run_event
    await coro(*args, **kwargs)
  File "bot.py", line 58, in on_message
    await message.author.send(embed=help)
  File "/home/bobwithacamera/.local/lib/python3.5/site-packages/discord/abc.py", line 823, in send
    data = await state.http.send_message(channel.id, content, tts=tts, embed=embed, nonce=nonce)
  File "/home/bobwithacamera/.local/lib/python3.5/site-packages/discord/http.py", line 218, in request
    raise Forbidden(r, data)
discord.errors.Forbidden: 403 FORBIDDEN (error code: 50007): Cannot send messages to this user
Ignoring exception in on_message
Traceback (most recent call last):
  File "/home/bobwithacamera/.local/lib/python3.5/site-packages/discord/client.py", line 270, in _run_event
    await coro(*args, **kwargs)
  File "bot.py", line 58, in on_message
    await message.author.send(embed=help)
  File "/home/bobwithacamera/.local/lib/python3.5/site-packages/discord/abc.py", line 823, in send
    data = await state.http.send_message(channel.id, content, tts=tts, embed=embed, nonce=nonce)
  File "/home/bobwithacamera/.local/lib/python3.5/site-packages/discord/http.py", line 218, in request
    raise Forbidden(r, data)
discord.errors.Forbidden: 403 FORBIDDEN (error code: 50007): Cannot send messages to this user
Ignoring exception in on_message
Traceback (most recent call last):
  File "/home/bobwithacamera/.local/lib/python3.5/site-packages/discord/client.py", line 270, in _run_event
    await coro(*args, **kwargs)
  File "bot.py", line 58, in on_message
    await message.author.send(embed=help)
  File "/home/bobwithacamera/.local/lib/python3.5/site-packages/discord/abc.py", line 823, in send
    data = await state.http.send_message(channel.id, content, tts=tts, embed=embed, nonce=nonce)
  File "/home/bobwithacamera/.local/lib/python3.5/site-packages/discord/http.py", line 218, in request
    raise Forbidden(r, data)
discord.errors.Forbidden: 403 FORBIDDEN (error code: 50007): Cannot send messages to this user
Ignoring exception in on_message
Traceback (most recent call last):
  File "/home/bobwithacamera/.local/lib/python3.5/site-packages/discord/client.py", line 270, in _run_event
    await coro(*args, **kwargs)
  File "bot.py", line 58, in on_message
    await message.author.send(embed=help)
  File "/home/bobwithacamera/.local/lib/python3.5/site-packages/discord/abc.py", line 823, in send
    data = await state.http.send_message(channel.id, content, tts=tts, embed=embed, nonce=nonce)
  File "/home/bobwithacamera/.local/lib/python3.5/site-packages/discord/http.py", line 218, in request
    raise Forbidden(r, data)
discord.errors.Forbidden: 403 FORBIDDEN (error code: 50007): Cannot send messages to this user
Ignoring exception in on_message
Traceback (most recent call last):
  File "/home/bobwithacamera/.local/lib/python3.5/site-packages/discord/client.py", line 270, in _run_event
    await coro(*args, **kwargs)
  File "bot.py", line 58, in on_message
    await message.author.send(embed=help)
  File "/home/bobwithacamera/.local/lib/python3.5/site-packages/discord/abc.py", line 823, in send
    data = await state.http.send_message(channel.id, content, tts=tts, embed=embed, nonce=nonce)
  File "/home/bobwithacamera/.local/lib/python3.5/site-packages/discord/http.py", line 218, in request
    raise Forbidden(r, data)
discord.errors.Forbidden: 403 FORBIDDEN (error code: 50007): Cannot send messages to this user
Ignoring exception in on_message
Traceback (most recent call last):
  File "/home/bobwithacamera/.local/lib/python3.5/site-packages/discord/client.py", line 270, in _run_event
    await coro(*args, **kwargs)
  File "bot.py", line 58, in on_message
    await message.author.send(embed=help)
  File "/home/bobwithacamera/.local/lib/python3.5/site-packages/discord/abc.py", line 823, in send
    data = await state.http.send_message(channel.id, content, tts=tts, embed=embed, nonce=nonce)
  File "/home/bobwithacamera/.local/lib/python3.5/site-packages/discord/http.py", line 218, in request
    raise Forbidden(r, data)
discord.errors.Forbidden: 403 FORBIDDEN (error code: 50007): Cannot send messages to this user
Ignoring exception in on_message
Traceback (most recent call last):
  File "/home/bobwithacamera/.local/lib/python3.5/site-packages/discord/client.py", line 270, in _run_event
    await coro(*args, **kwargs)
  File "bot.py", line 58, in on_message
    await message.author.send(embed=help)
  File "/home/bobwithacamera/.local/lib/python3.5/site-packages/discord/abc.py", line 823, in send
    data = await state.http.send_message(channel.id, content, tts=tts, embed=embed, nonce=nonce)
  File "/home/bobwithacamera/.local/lib/python3.5/site-packages/discord/http.py", line 218, in request
    raise Forbidden(r, data)
discord.errors.Forbidden: 403 FORBIDDEN (error code: 50007): Cannot send messages to this user
Ignoring exception in on_message
Traceback (most recent call last):
  File "/home/bobwithacamera/.local/lib/python3.5/site-packages/discord/client.py", line 270, in _run_event
    await coro(*args, **kwargs)
  File "bot.py", line 58, in on_message
    await message.author.send(embed=help)
  File "/home/bobwithacamera/.local/lib/python3.5/site-packages/discord/abc.py", line 823, in send
    data = await state.http.send_message(channel.id, content, tts=tts, embed=embed, nonce=nonce)
  File "/home/bobwithacamera/.local/lib/python3.5/site-packages/discord/http.py", line 218, in request
    raise Forbidden(r, data)
discord.errors.Forbidden: 403 FORBIDDEN (error code: 50007): Cannot send messages to this user
Ignoring exception in on_message
Traceback (most recent call last):
  File "/home/bobwithacamera/.local/lib/python3.5/site-packages/discord/client.py", line 270, in _run_event
    await coro(*args, **kwargs)
  File "bot.py", line 58, in on_message
    await message.author.send(embed=help)
  File "/home/bobwithacamera/.local/lib/python3.5/site-packages/discord/abc.py", line 823, in send
    data = await state.http.send_message(channel.id, content, tts=tts, embed=embed, nonce=nonce)
  File "/home/bobwithacamera/.local/lib/python3.5/site-packages/discord/http.py", line 218, in request
    raise Forbidden(r, data)
discord.errors.Forbidden: 403 FORBIDDEN (error code: 50007): Cannot send messages to this user
Ignoring exception in on_message
Traceback (most recent call last):
  File "bot.py", line 196, in on_message
    with open("users/" + user_id + '.json') as user_data:
FileNotFoundError: [Errno 2] No such file or directory: 'users/473127575426695168.json'

During handling of the above exception, another exception occurred:

Traceback (most recent call last):
  File "/home/bobwithacamera/.local/lib/python3.5/site-packages/discord/client.py", line 270, in _run_event
    await coro(*args, **kwargs)
  File "bot.py", line 227, in on_message
    await loadingMessage.edit(message.author.mention + ' No connected account')
TypeError: edit() takes 1 positional argument but 2 were given
Ignoring exception in on_message
Traceback (most recent call last):
  File "/home/bobwithacamera/.local/lib/python3.5/site-packages/discord/client.py", line 270, in _run_event
    await coro(*args, **kwargs)
  File "bot.py", line 251, in on_message
    with open("users/" + str(message.author.id) + '.json', 'w+') as outfile:
FileNotFoundError: [Errno 2] No such file or directory: 'users/473127575426695168.json'
Ignoring exception in on_message
Traceback (most recent call last):
  File "/home/bobwithacamera/.local/lib/python3.5/site-packages/discord/client.py", line 270, in _run_event
    await coro(*args, **kwargs)
  File "bot.py", line 251, in on_message
    with open("users/" + str(message.author.id) + '.json', 'w+') as outfile:
FileNotFoundError: [Errno 2] No such file or directory: 'users/473127575426695168.json'
Ignoring exception in on_message
Traceback (most recent call last):
  File "/home/bobwithacamera/.local/lib/python3.5/site-packages/discord/client.py", line 270, in _run_event
    await coro(*args, **kwargs)
  File "bot.py", line 78, in on_message
    for moderator in subreddit.moderator():
  File "/home/bobwithacamera/.local/lib/python3.5/site-packages/praw/models/reddit/subreddit.py", line 2032, in __call__
    return self.subreddit._reddit.get(url, params=params)
  File "/home/bobwithacamera/.local/lib/python3.5/site-packages/praw/reddit.py", line 442, in get
    data = self.request("GET", path, params=params)
  File "/home/bobwithacamera/.local/lib/python3.5/site-packages/praw/reddit.py", line 577, in request
    method, path, data=data, files=files, params=params
  File "/home/bobwithacamera/.local/lib/python3.5/site-packages/prawcore/sessions.py", line 185, in request
    params=params, url=url)
  File "/home/bobwithacamera/.local/lib/python3.5/site-packages/prawcore/sessions.py", line 130, in _request_with_retries
    raise self.STATUS_EXCEPTIONS[response.status_code](response)
prawcore.exceptions.NotFound: received 404 HTTP response
Ignoring exception in on_message
Traceback (most recent call last):
  File "/home/bobwithacamera/.local/lib/python3.5/site-packages/discord/client.py", line 270, in _run_event
    await coro(*args, **kwargs)
  File "bot.py", line 251, in on_message
    with open("users/" + str(message.author.id) + '.json', 'w+') as outfile:
FileNotFoundError: [Errno 2] No such file or directory: 'users/404995222960078859.json'
Ignoring exception in on_message
Traceback (most recent call last):
  File "/home/bobwithacamera/.local/lib/python3.5/site-packages/discord/client.py", line 270, in _run_event
    await coro(*args, **kwargs)
  File "bot.py", line 236, in on_message
    user_r = reddit.redditor(user_name)
  File "/home/bobwithacamera/.local/lib/python3.5/site-packages/praw/reddit.py", line 561, in redditor
    return models.Redditor(self, name)
  File "/home/bobwithacamera/.local/lib/python3.5/site-packages/praw/models/reddit/redditor.py", line 113, in __init__
    raise TypeError("Either `name` or `_data` must be provided.")
TypeError: Either `name` or `_data` must be provided.
Ignoring exception in on_message
Traceback (most recent call last):
  File "/home/bobwithacamera/.local/lib/python3.5/site-packages/discord/client.py", line 270, in _run_event
    await coro(*args, **kwargs)
  File "bot.py", line 251, in on_message
    with open("users/" + str(message.author.id) + '.json', 'w+') as outfile:
FileNotFoundError: [Errno 2] No such file or directory: 'users/404995222960078859.json'
Ignoring exception in on_message
Traceback (most recent call last):
  File "/home/bobwithacamera/.local/lib/python3.5/site-packages/discord/client.py", line 270, in _run_event
    await coro(*args, **kwargs)
  File "bot.py", line 78, in on_message
    for moderator in subreddit.moderator():
  File "/home/bobwithacamera/.local/lib/python3.5/site-packages/praw/models/reddit/subreddit.py", line 2032, in __call__
    return self.subreddit._reddit.get(url, params=params)
  File "/home/bobwithacamera/.local/lib/python3.5/site-packages/praw/reddit.py", line 442, in get
    data = self.request("GET", path, params=params)
  File "/home/bobwithacamera/.local/lib/python3.5/site-packages/praw/reddit.py", line 577, in request
    method, path, data=data, files=files, params=params
  File "/home/bobwithacamera/.local/lib/python3.5/site-packages/prawcore/sessions.py", line 185, in request
    params=params, url=url)
  File "/home/bobwithacamera/.local/lib/python3.5/site-packages/prawcore/sessions.py", line 130, in _request_with_retries
    raise self.STATUS_EXCEPTIONS[response.status_code](response)
prawcore.exceptions.NotFound: received 404 HTTP response
Ignoring exception in on_message
Traceback (most recent call last):
  File "/home/bobwithacamera/.local/lib/python3.5/site-packages/discord/client.py", line 270, in _run_event
    await coro(*args, **kwargs)
  File "bot.py", line 78, in on_message
    for moderator in subreddit.moderator():
  File "/home/bobwithacamera/.local/lib/python3.5/site-packages/praw/models/reddit/subreddit.py", line 2032, in __call__
    return self.subreddit._reddit.get(url, params=params)
  File "/home/bobwithacamera/.local/lib/python3.5/site-packages/praw/reddit.py", line 442, in get
    data = self.request("GET", path, params=params)
  File "/home/bobwithacamera/.local/lib/python3.5/site-packages/praw/reddit.py", line 577, in request
    method, path, data=data, files=files, params=params
  File "/home/bobwithacamera/.local/lib/python3.5/site-packages/prawcore/sessions.py", line 185, in request
    params=params, url=url)
  File "/home/bobwithacamera/.local/lib/python3.5/site-packages/prawcore/sessions.py", line 130, in _request_with_retries
    raise self.STATUS_EXCEPTIONS[response.status_code](response)
prawcore.exceptions.NotFound: received 404 HTTP response
Ignoring exception in on_message
Traceback (most recent call last):
  File "/home/bobwithacamera/.local/lib/python3.5/site-packages/discord/client.py", line 270, in _run_event
    await coro(*args, **kwargs)
  File "bot.py", line 179, in on_message
    user.add_field(name='Karma:', value=user_r.comment_karma, inline=False)
  File "/home/bobwithacamera/.local/lib/python3.5/site-packages/praw/models/reddit/base.py", line 30, in __getattr__
    self._fetch()
  File "/home/bobwithacamera/.local/lib/python3.5/site-packages/praw/models/reddit/redditor.py", line 133, in _fetch
    data = self._fetch_data()
  File "/home/bobwithacamera/.local/lib/python3.5/site-packages/praw/models/reddit/redditor.py", line 130, in _fetch_data
    return self._reddit.request("GET", path, params)
  File "/home/bobwithacamera/.local/lib/python3.5/site-packages/praw/reddit.py", line 577, in request
    method, path, data=data, files=files, params=params
  File "/home/bobwithacamera/.local/lib/python3.5/site-packages/prawcore/sessions.py", line 185, in request
    params=params, url=url)
  File "/home/bobwithacamera/.local/lib/python3.5/site-packages/prawcore/sessions.py", line 130, in _request_with_retries
    raise self.STATUS_EXCEPTIONS[response.status_code](response)
prawcore.exceptions.NotFound: received 404 HTTP response
Ignoring exception in on_message
Traceback (most recent call last):
  File "/home/bobwithacamera/.local/lib/python3.5/site-packages/discord/client.py", line 270, in _run_event
    await coro(*args, **kwargs)
  File "bot.py", line 78, in on_message
    for moderator in subreddit.moderator():
  File "/home/bobwithacamera/.local/lib/python3.5/site-packages/praw/models/reddit/subreddit.py", line 2032, in __call__
    return self.subreddit._reddit.get(url, params=params)
  File "/home/bobwithacamera/.local/lib/python3.5/site-packages/praw/reddit.py", line 442, in get
    data = self.request("GET", path, params=params)
  File "/home/bobwithacamera/.local/lib/python3.5/site-packages/praw/reddit.py", line 577, in request
    method, path, data=data, files=files, params=params
  File "/home/bobwithacamera/.local/lib/python3.5/site-packages/prawcore/sessions.py", line 185, in request
    params=params, url=url)
  File "/home/bobwithacamera/.local/lib/python3.5/site-packages/prawcore/sessions.py", line 130, in _request_with_retries
    raise self.STATUS_EXCEPTIONS[response.status_code](response)
prawcore.exceptions.NotFound: received 404 HTTP response
Ignoring exception in on_message
Traceback (most recent call last):
  File "/home/bobwithacamera/.local/lib/python3.5/site-packages/discord/client.py", line 270, in _run_event
    await coro(*args, **kwargs)
  File "bot.py", line 179, in on_message
    user.add_field(name='Karma:', value=user_r.comment_karma, inline=False)
  File "/home/bobwithacamera/.local/lib/python3.5/site-packages/praw/models/reddit/base.py", line 30, in __getattr__
    self._fetch()
  File "/home/bobwithacamera/.local/lib/python3.5/site-packages/praw/models/reddit/redditor.py", line 133, in _fetch
    data = self._fetch_data()
  File "/home/bobwithacamera/.local/lib/python3.5/site-packages/praw/models/reddit/redditor.py", line 130, in _fetch_data
    return self._reddit.request("GET", path, params)
  File "/home/bobwithacamera/.local/lib/python3.5/site-packages/praw/reddit.py", line 577, in request
    method, path, data=data, files=files, params=params
  File "/home/bobwithacamera/.local/lib/python3.5/site-packages/prawcore/sessions.py", line 185, in request
    params=params, url=url)
  File "/home/bobwithacamera/.local/lib/python3.5/site-packages/prawcore/sessions.py", line 130, in _request_with_retries
    raise self.STATUS_EXCEPTIONS[response.status_code](response)
prawcore.exceptions.NotFound: received 404 HTTP response
Ignoring exception in on_message
Traceback (most recent call last):
  File "/home/bobwithacamera/.local/lib/python3.5/site-packages/discord/client.py", line 270, in _run_event
    await coro(*args, **kwargs)
  File "bot.py", line 78, in on_message
    for moderator in subreddit.moderator():
  File "/home/bobwithacamera/.local/lib/python3.5/site-packages/praw/models/reddit/subreddit.py", line 2032, in __call__
    return self.subreddit._reddit.get(url, params=params)
  File "/home/bobwithacamera/.local/lib/python3.5/site-packages/praw/reddit.py", line 442, in get
    data = self.request("GET", path, params=params)
  File "/home/bobwithacamera/.local/lib/python3.5/site-packages/praw/reddit.py", line 577, in request
    method, path, data=data, files=files, params=params
  File "/home/bobwithacamera/.local/lib/python3.5/site-packages/prawcore/sessions.py", line 185, in request
    params=params, url=url)
  File "/home/bobwithacamera/.local/lib/python3.5/site-packages/prawcore/sessions.py", line 130, in _request_with_retries
    raise self.STATUS_EXCEPTIONS[response.status_code](response)
prawcore.exceptions.NotFound: received 404 HTTP response
Ignoring exception in on_message
Traceback (most recent call last):
  File "bot.py", line 196, in on_message
    with open("users/" + user_id + '.json') as user_data:
FileNotFoundError: [Errno 2] No such file or directory: 'users/404995222960078859.json'

During handling of the above exception, another exception occurred:

Traceback (most recent call last):
  File "/home/bobwithacamera/.local/lib/python3.5/site-packages/discord/client.py", line 270, in _run_event
    await coro(*args, **kwargs)
  File "bot.py", line 227, in on_message
    await loadingMessage.edit(message.author.mention + ' No connected account')
TypeError: edit() takes 1 positional argument but 2 were given
Ignoring exception in on_message
Traceback (most recent call last):
  File "/home/bobwithacamera/.local/lib/python3.5/site-packages/discord/client.py", line 270, in _run_event
    await coro(*args, **kwargs)
  File "bot.py", line 251, in on_message
    with open("users/" + str(message.author.id) + '.json', 'w+') as outfile:
FileNotFoundError: [Errno 2] No such file or directory: 'users/404995222960078859.json'
Ignoring exception in on_message
Traceback (most recent call last):
  File "/home/bobwithacamera/.local/lib/python3.5/site-packages/discord/client.py", line 270, in _run_event
    await coro(*args, **kwargs)
  File "bot.py", line 251, in on_message
    with open("users/" + str(message.author.id) + '.json', 'w+') as outfile:
FileNotFoundError: [Errno 2] No such file or directory: 'users/404995222960078859.json'
Ignoring exception in on_message
Traceback (most recent call last):
  File "/home/bobwithacamera/.local/lib/python3.5/site-packages/discord/client.py", line 270, in _run_event
    await coro(*args, **kwargs)
  File "bot.py", line 251, in on_message
    with open("users/" + str(message.author.id) + '.json', 'w+') as outfile:
FileNotFoundError: [Errno 2] No such file or directory: 'users/404995222960078859.json'
Ignoring exception in on_message
Traceback (most recent call last):
  File "/home/bobwithacamera/.local/lib/python3.5/site-packages/discord/client.py", line 270, in _run_event
    await coro(*args, **kwargs)
  File "bot.py", line 251, in on_message
    with open("users/" + str(message.author.id) + '.json', 'w+') as outfile:
FileNotFoundError: [Errno 2] No such file or directory: 'users/404995222960078859.json'
Ignoring exception in on_message
Traceback (most recent call last):
  File "/home/bobwithacamera/.local/lib/python3.5/site-packages/discord/client.py", line 270, in _run_event
    await coro(*args, **kwargs)
  File "bot.py", line 251, in on_message
    with open("users/" + str(message.author.id) + '.json', 'w+') as outfile:
FileNotFoundError: [Errno 2] No such file or directory: 'users/404995222960078859.json'
Ignoring exception in on_message
Traceback (most recent call last):
  File "/home/bobwithacamera/.local/lib/python3.5/site-packages/discord/client.py", line 270, in _run_event
    await coro(*args, **kwargs)
  File "bot.py", line 251, in on_message
    with open("users/" + str(message.author.id) + '.json', 'w+') as outfile:
FileNotFoundError: [Errno 2] No such file or directory: 'users/404995222960078859.json'
Ignoring exception in on_message
Traceback (most recent call last):
  File "/home/bobwithacamera/.local/lib/python3.5/site-packages/discord/client.py", line 270, in _run_event
    await coro(*args, **kwargs)
  File "bot.py", line 251, in on_message
    with open("users/" + str(message.author.id) + '.json', 'w+') as outfile:
FileNotFoundError: [Errno 2] No such file or directory: 'users/404995222960078859.json'
Ignoring exception in on_message
Traceback (most recent call last):
  File "/home/bobwithacamera/.local/lib/python3.5/site-packages/discord/client.py", line 270, in _run_event
    await coro(*args, **kwargs)
  File "bot.py", line 251, in on_message
    with open("users/" + str(message.author.id) + '.json', 'w+') as outfile:
FileNotFoundError: [Errno 2] No such file or directory: 'users/404995222960078859.json'
Ignoring exception in on_message
Traceback (most recent call last):
  File "/home/bobwithacamera/.local/lib/python3.5/site-packages/discord/client.py", line 270, in _run_event
    await coro(*args, **kwargs)
  File "bot.py", line 251, in on_message
    with open("users/" + str(message.author.id) + '.json', 'w+') as outfile:
FileNotFoundError: [Errno 2] No such file or directory: 'users/404995222960078859.json'
Ignoring exception in on_message
Traceback (most recent call last):
  File "/home/bobwithacamera/.local/lib/python3.5/site-packages/discord/client.py", line 270, in _run_event
    await coro(*args, **kwargs)
  File "bot.py", line 251, in on_message
    with open("users/" + str(message.author.id) + '.json', 'w+') as outfile:
FileNotFoundError: [Errno 2] No such file or directory: 'users/404995222960078859.json'
Ignoring exception in on_message
Traceback (most recent call last):
  File "/home/bobwithacamera/.local/lib/python3.5/site-packages/discord/client.py", line 270, in _run_event
    await coro(*args, **kwargs)
  File "bot.py", line 251, in on_message
    with open("users/" + str(message.author.id) + '.json', 'w+') as outfile:
FileNotFoundError: [Errno 2] No such file or directory: 'users/404995222960078859.json'
Ignoring exception in on_message
Traceback (most recent call last):
  File "/home/bobwithacamera/.local/lib/python3.5/site-packages/discord/client.py", line 270, in _run_event
    await coro(*args, **kwargs)
  File "bot.py", line 78, in on_message
    for moderator in subreddit.moderator():
  File "/home/bobwithacamera/.local/lib/python3.5/site-packages/praw/models/reddit/subreddit.py", line 2032, in __call__
    return self.subreddit._reddit.get(url, params=params)
  File "/home/bobwithacamera/.local/lib/python3.5/site-packages/praw/reddit.py", line 442, in get
    data = self.request("GET", path, params=params)
  File "/home/bobwithacamera/.local/lib/python3.5/site-packages/praw/reddit.py", line 577, in request
    method, path, data=data, files=files, params=params
  File "/home/bobwithacamera/.local/lib/python3.5/site-packages/prawcore/sessions.py", line 185, in request
    params=params, url=url)
  File "/home/bobwithacamera/.local/lib/python3.5/site-packages/prawcore/sessions.py", line 130, in _request_with_retries
    raise self.STATUS_EXCEPTIONS[response.status_code](response)
prawcore.exceptions.NotFound: received 404 HTTP response
Ignoring exception in on_message
Traceback (most recent call last):
  File "/home/bobwithacamera/.local/lib/python3.5/site-packages/discord/client.py", line 270, in _run_event
    await coro(*args, **kwargs)
  File "bot.py", line 251, in on_message
    with open("users/" + str(message.author.id) + '.json', 'w+') as outfile:
FileNotFoundError: [Errno 2] No such file or directory: 'users/404995222960078859.json'
Ignoring exception in on_message
Traceback (most recent call last):
  File "/home/bobwithacamera/.local/lib/python3.5/site-packages/discord/client.py", line 270, in _run_event
    await coro(*args, **kwargs)
  File "bot.py", line 251, in on_message
    with open("users/" + str(message.author.id) + '.json', 'w+') as outfile:
FileNotFoundError: [Errno 2] No such file or directory: 'users/404995222960078859.json'
Ignoring exception in on_message
Traceback (most recent call last):
  File "/home/bobwithacamera/.local/lib/python3.5/site-packages/discord/client.py", line 270, in _run_event
    await coro(*args, **kwargs)
  File "bot.py", line 251, in on_message
    with open("users/" + str(message.author.id) + '.json', 'w+') as outfile:
FileNotFoundError: [Errno 2] No such file or directory: 'users/404995222960078859.json'
Ignoring exception in on_message
Traceback (most recent call last):
  File "/home/bobwithacamera/.local/lib/python3.5/site-packages/discord/client.py", line 270, in _run_event
    await coro(*args, **kwargs)
  File "bot.py", line 251, in on_message
    with open("users/" + str(message.author.id) + '.json', 'w+') as outfile:
FileNotFoundError: [Errno 2] No such file or directory: 'users/404995222960078859.json'
Ignoring exception in on_message
Traceback (most recent call last):
  File "/home/bobwithacamera/.local/lib/python3.5/site-packages/discord/client.py", line 270, in _run_event
    await coro(*args, **kwargs)
  File "bot.py", line 179, in on_message
    user.add_field(name='Karma:', value=user_r.comment_karma, inline=False)
  File "/home/bobwithacamera/.local/lib/python3.5/site-packages/praw/models/reddit/base.py", line 30, in __getattr__
    self._fetch()
  File "/home/bobwithacamera/.local/lib/python3.5/site-packages/praw/models/reddit/redditor.py", line 133, in _fetch
    data = self._fetch_data()
  File "/home/bobwithacamera/.local/lib/python3.5/site-packages/praw/models/reddit/redditor.py", line 130, in _fetch_data
    return self._reddit.request("GET", path, params)
  File "/home/bobwithacamera/.local/lib/python3.5/site-packages/praw/reddit.py", line 577, in request
    method, path, data=data, files=files, params=params
  File "/home/bobwithacamera/.local/lib/python3.5/site-packages/prawcore/sessions.py", line 185, in request
    params=params, url=url)
  File "/home/bobwithacamera/.local/lib/python3.5/site-packages/prawcore/sessions.py", line 130, in _request_with_retries
    raise self.STATUS_EXCEPTIONS[response.status_code](response)
prawcore.exceptions.NotFound: received 404 HTTP response
Ignoring exception in on_message
Traceback (most recent call last):
  File "/home/bobwithacamera/.local/lib/python3.5/site-packages/discord/client.py", line 270, in _run_event
    await coro(*args, **kwargs)
  File "bot.py", line 251, in on_message
    with open("users/" + str(message.author.id) + '.json', 'w+') as outfile:
FileNotFoundError: [Errno 2] No such file or directory: 'users/404995222960078859.json'
Ignoring exception in on_message
Traceback (most recent call last):
  File "/home/bobwithacamera/.local/lib/python3.5/site-packages/discord/client.py", line 270, in _run_event
    await coro(*args, **kwargs)
  File "bot.py", line 78, in on_message
    for moderator in subreddit.moderator():
  File "/home/bobwithacamera/.local/lib/python3.5/site-packages/praw/models/reddit/subreddit.py", line 2032, in __call__
    return self.subreddit._reddit.get(url, params=params)
  File "/home/bobwithacamera/.local/lib/python3.5/site-packages/praw/reddit.py", line 442, in get
    data = self.request("GET", path, params=params)
  File "/home/bobwithacamera/.local/lib/python3.5/site-packages/praw/reddit.py", line 577, in request
    method, path, data=data, files=files, params=params
  File "/home/bobwithacamera/.local/lib/python3.5/site-packages/prawcore/sessions.py", line 185, in request
    params=params, url=url)
  File "/home/bobwithacamera/.local/lib/python3.5/site-packages/prawcore/sessions.py", line 130, in _request_with_retries
    raise self.STATUS_EXCEPTIONS[response.status_code](response)
prawcore.exceptions.Redirect: Redirect to /subreddits/search
Ignoring exception in on_message
Traceback (most recent call last):
  File "/home/bobwithacamera/.local/lib/python3.5/site-packages/discord/client.py", line 270, in _run_event
    await coro(*args, **kwargs)
  File "bot.py", line 251, in on_message
    with open("users/" + str(message.author.id) + '.json', 'w+') as outfile:
FileNotFoundError: [Errno 2] No such file or directory: 'users/404995222960078859.json'
Ignoring exception in on_message
Traceback (most recent call last):
  File "/home/bobwithacamera/.local/lib/python3.5/site-packages/discord/client.py", line 270, in _run_event
    await coro(*args, **kwargs)
  File "bot.py", line 251, in on_message
    with open("users/" + str(message.author.id) + '.json', 'w+') as outfile:
FileNotFoundError: [Errno 2] No such file or directory: 'users/404995222960078859.json'
Ignoring exception in on_message
Traceback (most recent call last):
  File "/home/bobwithacamera/.local/lib/python3.5/site-packages/discord/client.py", line 270, in _run_event
    await coro(*args, **kwargs)
  File "bot.py", line 251, in on_message
    with open("users/" + str(message.author.id) + '.json', 'w+') as outfile:
FileNotFoundError: [Errno 2] No such file or directory: 'users/404995222960078859.json'
Ignoring exception in on_message
Traceback (most recent call last):
  File "/home/bobwithacamera/.local/lib/python3.5/site-packages/discord/client.py", line 270, in _run_event
    await coro(*args, **kwargs)
  File "bot.py", line 251, in on_message
    with open("users/" + str(message.author.id) + '.json', 'w+') as outfile:
FileNotFoundError: [Errno 2] No such file or directory: 'users/404995222960078859.json'
Ignoring exception in on_message
Traceback (most recent call last):
  File "/home/bobwithacamera/.local/lib/python3.5/site-packages/discord/client.py", line 270, in _run_event
    await coro(*args, **kwargs)
  File "bot.py", line 251, in on_message
    with open("users/" + str(message.author.id) + '.json', 'w+') as outfile:
FileNotFoundError: [Errno 2] No such file or directory: 'users/404995222960078859.json'
Ignoring exception in on_message
Traceback (most recent call last):
  File "/home/bobwithacamera/.local/lib/python3.5/site-packages/discord/client.py", line 270, in _run_event
    await coro(*args, **kwargs)
  File "bot.py", line 251, in on_message
    with open("users/" + str(message.author.id) + '.json', 'w+') as outfile:
FileNotFoundError: [Errno 2] No such file or directory: 'users/404995222960078859.json'
Ignoring exception in on_message
Traceback (most recent call last):
  File "/home/bobwithacamera/.local/lib/python3.5/site-packages/discord/client.py", line 270, in _run_event
    await coro(*args, **kwargs)
  File "bot.py", line 251, in on_message
    with open("users/" + str(message.author.id) + '.json', 'w+') as outfile:
FileNotFoundError: [Errno 2] No such file or directory: 'users/404995222960078859.json'
Ignoring exception in on_message
Traceback (most recent call last):
  File "/home/bobwithacamera/.local/lib/python3.5/site-packages/discord/client.py", line 270, in _run_event
    await coro(*args, **kwargs)
  File "bot.py", line 251, in on_message
    with open("users/" + str(message.author.id) + '.json', 'w+') as outfile:
FileNotFoundError: [Errno 2] No such file or directory: 'users/404995222960078859.json'
Ignoring exception in on_message
Traceback (most recent call last):
  File "bot.py", line 196, in on_message
    with open("users/" + user_id + '.json') as user_data:
FileNotFoundError: [Errno 2] No such file or directory: 'users/404995222960078859.json'

During handling of the above exception, another exception occurred:

Traceback (most recent call last):
  File "/home/bobwithacamera/.local/lib/python3.5/site-packages/discord/client.py", line 270, in _run_event
    await coro(*args, **kwargs)
  File "bot.py", line 227, in on_message
    await loadingMessage.edit(message.author.mention + ' No connected account')
TypeError: edit() takes 1 positional argument but 2 were given
Ignoring exception in on_message
Traceback (most recent call last):
  File "/home/bobwithacamera/.local/lib/python3.5/site-packages/discord/client.py", line 270, in _run_event
    await coro(*args, **kwargs)
  File "bot.py", line 78, in on_message
    for moderator in subreddit.moderator():
  File "/home/bobwithacamera/.local/lib/python3.5/site-packages/praw/models/reddit/subreddit.py", line 2032, in __call__
    return self.subreddit._reddit.get(url, params=params)
  File "/home/bobwithacamera/.local/lib/python3.5/site-packages/praw/reddit.py", line 442, in get
    data = self.request("GET", path, params=params)
  File "/home/bobwithacamera/.local/lib/python3.5/site-packages/praw/reddit.py", line 577, in request
    method, path, data=data, files=files, params=params
  File "/home/bobwithacamera/.local/lib/python3.5/site-packages/prawcore/sessions.py", line 185, in request
    params=params, url=url)
  File "/home/bobwithacamera/.local/lib/python3.5/site-packages/prawcore/sessions.py", line 130, in _request_with_retries
    raise self.STATUS_EXCEPTIONS[response.status_code](response)
prawcore.exceptions.Redirect: Redirect to /subreddits/search
Ignoring exception in on_message
Traceback (most recent call last):
  File "/home/bobwithacamera/.local/lib/python3.5/site-packages/discord/client.py", line 270, in _run_event
    await coro(*args, **kwargs)
  File "bot.py", line 251, in on_message
    with open("users/" + str(message.author.id) + '.json', 'w+') as outfile:
FileNotFoundError: [Errno 2] No such file or directory: 'users/404995222960078859.json'
Ignoring exception in on_message
Traceback (most recent call last):
  File "/home/bobwithacamera/.local/lib/python3.5/site-packages/discord/client.py", line 270, in _run_event
    await coro(*args, **kwargs)
  File "bot.py", line 179, in on_message
    user.add_field(name='Karma:', value=user_r.comment_karma, inline=False)
  File "/home/bobwithacamera/.local/lib/python3.5/site-packages/praw/models/reddit/base.py", line 30, in __getattr__
    self._fetch()
  File "/home/bobwithacamera/.local/lib/python3.5/site-packages/praw/models/reddit/redditor.py", line 133, in _fetch
    data = self._fetch_data()
  File "/home/bobwithacamera/.local/lib/python3.5/site-packages/praw/models/reddit/redditor.py", line 130, in _fetch_data
    return self._reddit.request("GET", path, params)
  File "/home/bobwithacamera/.local/lib/python3.5/site-packages/praw/reddit.py", line 577, in request
    method, path, data=data, files=files, params=params
  File "/home/bobwithacamera/.local/lib/python3.5/site-packages/prawcore/sessions.py", line 185, in request
    params=params, url=url)
  File "/home/bobwithacamera/.local/lib/python3.5/site-packages/prawcore/sessions.py", line 130, in _request_with_retries
    raise self.STATUS_EXCEPTIONS[response.status_code](response)
prawcore.exceptions.NotFound: received 404 HTTP response
Ignoring exception in on_message
Traceback (most recent call last):
  File "/home/bobwithacamera/.local/lib/python3.5/site-packages/discord/client.py", line 270, in _run_event
    await coro(*args, **kwargs)
  File "bot.py", line 58, in on_message
    await message.author.send(embed=help)
  File "/home/bobwithacamera/.local/lib/python3.5/site-packages/discord/abc.py", line 823, in send
    data = await state.http.send_message(channel.id, content, tts=tts, embed=embed, nonce=nonce)
  File "/home/bobwithacamera/.local/lib/python3.5/site-packages/discord/http.py", line 218, in request
    raise Forbidden(r, data)
discord.errors.Forbidden: 403 FORBIDDEN (error code: 50007): Cannot send messages to this user
Ignoring exception in on_message
Traceback (most recent call last):
  File "/home/bobwithacamera/.local/lib/python3.5/site-packages/discord/client.py", line 270, in _run_event
    await coro(*args, **kwargs)
  File "bot.py", line 58, in on_message
    await message.author.send(embed=help)
  File "/home/bobwithacamera/.local/lib/python3.5/site-packages/discord/abc.py", line 791, in send
    channel = await self._get_channel()
  File "/home/bobwithacamera/.local/lib/python3.5/site-packages/discord/user.py", line 659, in _get_channel
    ch = await self.create_dm()
  File "/home/bobwithacamera/.local/lib/python3.5/site-packages/discord/user.py", line 682, in create_dm
    data = await state.http.start_private_message(self.id)
  File "/home/bobwithacamera/.local/lib/python3.5/site-packages/discord/http.py", line 222, in request
    raise HTTPException(r, data)
discord.errors.HTTPException: 400 BAD REQUEST (error code: 50033): Invalid Recipient(s)
Ignoring exception in on_message
Traceback (most recent call last):
  File "/home/bobwithacamera/.local/lib/python3.5/site-packages/discord/client.py", line 270, in _run_event
    await coro(*args, **kwargs)
  File "bot.py", line 78, in on_message
    for moderator in subreddit.moderator():
  File "/home/bobwithacamera/.local/lib/python3.5/site-packages/praw/models/reddit/subreddit.py", line 2032, in __call__
    return self.subreddit._reddit.get(url, params=params)
  File "/home/bobwithacamera/.local/lib/python3.5/site-packages/praw/reddit.py", line 442, in get
    data = self.request("GET", path, params=params)
  File "/home/bobwithacamera/.local/lib/python3.5/site-packages/praw/reddit.py", line 577, in request
    method, path, data=data, files=files, params=params
  File "/home/bobwithacamera/.local/lib/python3.5/site-packages/prawcore/sessions.py", line 185, in request
    params=params, url=url)
  File "/home/bobwithacamera/.local/lib/python3.5/site-packages/prawcore/sessions.py", line 130, in _request_with_retries
    raise self.STATUS_EXCEPTIONS[response.status_code](response)
prawcore.exceptions.Redirect: Redirect to /subreddits/search
Ignoring exception in on_message
Traceback (most recent call last):
  File "/home/bobwithacamera/.local/lib/python3.5/site-packages/discord/client.py", line 270, in _run_event
    await coro(*args, **kwargs)
  File "bot.py", line 58, in on_message
    await message.author.send(embed=help)
  File "/home/bobwithacamera/.local/lib/python3.5/site-packages/discord/abc.py", line 823, in send
    data = await state.http.send_message(channel.id, content, tts=tts, embed=embed, nonce=nonce)
  File "/home/bobwithacamera/.local/lib/python3.5/site-packages/discord/http.py", line 218, in request
    raise Forbidden(r, data)
discord.errors.Forbidden: 403 FORBIDDEN (error code: 50007): Cannot send messages to this user
Ignoring exception in on_message
Traceback (most recent call last):
  File "/home/bobwithacamera/.local/lib/python3.5/site-packages/discord/client.py", line 270, in _run_event
    await coro(*args, **kwargs)
  File "bot.py", line 58, in on_message
    await message.author.send(embed=help)
  File "/home/bobwithacamera/.local/lib/python3.5/site-packages/discord/abc.py", line 823, in send
    data = await state.http.send_message(channel.id, content, tts=tts, embed=embed, nonce=nonce)
  File "/home/bobwithacamera/.local/lib/python3.5/site-packages/discord/http.py", line 218, in request
    raise Forbidden(r, data)
discord.errors.Forbidden: 403 FORBIDDEN (error code: 50007): Cannot send messages to this user
Ignoring exception in on_message
Traceback (most recent call last):
  File "/home/bobwithacamera/.local/lib/python3.5/site-packages/discord/client.py", line 270, in _run_event
    await coro(*args, **kwargs)
  File "bot.py", line 58, in on_message
    await message.author.send(embed=help)
  File "/home/bobwithacamera/.local/lib/python3.5/site-packages/discord/abc.py", line 823, in send
    data = await state.http.send_message(channel.id, content, tts=tts, embed=embed, nonce=nonce)
  File "/home/bobwithacamera/.local/lib/python3.5/site-packages/discord/http.py", line 218, in request
    raise Forbidden(r, data)
discord.errors.Forbidden: 403 FORBIDDEN (error code: 50007): Cannot send messages to this user
Ignoring exception in on_message
Traceback (most recent call last):
  File "/home/bobwithacamera/.local/lib/python3.5/site-packages/discord/client.py", line 270, in _run_event
    await coro(*args, **kwargs)
  File "bot.py", line 251, in on_message
    with open("users/" + str(message.author.id) + '.json', 'w+') as outfile:
FileNotFoundError: [Errno 2] No such file or directory: 'users/211664151045472256.json'
Ignoring exception in on_message
Traceback (most recent call last):
  File "/home/bobwithacamera/.local/lib/python3.5/site-packages/discord/client.py", line 270, in _run_event
    await coro(*args, **kwargs)
  File "bot.py", line 58, in on_message
    await message.author.send(embed=help)
  File "/home/bobwithacamera/.local/lib/python3.5/site-packages/discord/abc.py", line 823, in send
    data = await state.http.send_message(channel.id, content, tts=tts, embed=embed, nonce=nonce)
  File "/home/bobwithacamera/.local/lib/python3.5/site-packages/discord/http.py", line 218, in request
    raise Forbidden(r, data)
discord.errors.Forbidden: 403 FORBIDDEN (error code: 50007): Cannot send messages to this user
Ignoring exception in on_message
Traceback (most recent call last):
  File "/home/bobwithacamera/.local/lib/python3.5/site-packages/discord/client.py", line 270, in _run_event
    await coro(*args, **kwargs)
  File "bot.py", line 58, in on_message
    await message.author.send(embed=help)
  File "/home/bobwithacamera/.local/lib/python3.5/site-packages/discord/abc.py", line 823, in send
    data = await state.http.send_message(channel.id, content, tts=tts, embed=embed, nonce=nonce)
  File "/home/bobwithacamera/.local/lib/python3.5/site-packages/discord/http.py", line 218, in request
    raise Forbidden(r, data)
discord.errors.Forbidden: 403 FORBIDDEN (error code: 50007): Cannot send messages to this user
Ignoring exception in on_message
Traceback (most recent call last):
  File "/home/bobwithacamera/.local/lib/python3.5/site-packages/discord/client.py", line 270, in _run_event
    await coro(*args, **kwargs)
  File "bot.py", line 58, in on_message
    await message.author.send(embed=help)
  File "/home/bobwithacamera/.local/lib/python3.5/site-packages/discord/abc.py", line 823, in send
    data = await state.http.send_message(channel.id, content, tts=tts, embed=embed, nonce=nonce)
  File "/home/bobwithacamera/.local/lib/python3.5/site-packages/discord/http.py", line 218, in request
    raise Forbidden(r, data)
discord.errors.Forbidden: 403 FORBIDDEN (error code: 50007): Cannot send messages to this user
Ignoring exception in on_message
Traceback (most recent call last):
  File "/home/bobwithacamera/.local/lib/python3.5/site-packages/discord/client.py", line 270, in _run_event
    await coro(*args, **kwargs)
  File "bot.py", line 58, in on_message
    await message.author.send(embed=help)
  File "/home/bobwithacamera/.local/lib/python3.5/site-packages/discord/abc.py", line 823, in send
    data = await state.http.send_message(channel.id, content, tts=tts, embed=embed, nonce=nonce)
  File "/home/bobwithacamera/.local/lib/python3.5/site-packages/discord/http.py", line 218, in request
    raise Forbidden(r, data)
discord.errors.Forbidden: 403 FORBIDDEN (error code: 50007): Cannot send messages to this user
Ignoring exception in on_message
Traceback (most recent call last):
  File "/home/bobwithacamera/.local/lib/python3.5/site-packages/discord/client.py", line 270, in _run_event
    await coro(*args, **kwargs)
  File "bot.py", line 58, in on_message
    await message.author.send(embed=help)
  File "/home/bobwithacamera/.local/lib/python3.5/site-packages/discord/abc.py", line 823, in send
    data = await state.http.send_message(channel.id, content, tts=tts, embed=embed, nonce=nonce)
  File "/home/bobwithacamera/.local/lib/python3.5/site-packages/discord/http.py", line 218, in request
    raise Forbidden(r, data)
discord.errors.Forbidden: 403 FORBIDDEN (error code: 50007): Cannot send messages to this user
Ignoring exception in on_message
Traceback (most recent call last):
  File "/home/bobwithacamera/.local/lib/python3.5/site-packages/discord/client.py", line 270, in _run_event
    await coro(*args, **kwargs)
  File "bot.py", line 58, in on_message
    await message.author.send(embed=help)
  File "/home/bobwithacamera/.local/lib/python3.5/site-packages/discord/abc.py", line 823, in send
    data = await state.http.send_message(channel.id, content, tts=tts, embed=embed, nonce=nonce)
  File "/home/bobwithacamera/.local/lib/python3.5/site-packages/discord/http.py", line 218, in request
    raise Forbidden(r, data)
discord.errors.Forbidden: 403 FORBIDDEN (error code: 50007): Cannot send messages to this user
Ignoring exception in on_message
Traceback (most recent call last):
  File "/home/bobwithacamera/.local/lib/python3.5/site-packages/discord/client.py", line 270, in _run_event
    await coro(*args, **kwargs)
  File "bot.py", line 58, in on_message
    await message.author.send(embed=help)
  File "/home/bobwithacamera/.local/lib/python3.5/site-packages/discord/abc.py", line 823, in send
    data = await state.http.send_message(channel.id, content, tts=tts, embed=embed, nonce=nonce)
  File "/home/bobwithacamera/.local/lib/python3.5/site-packages/discord/http.py", line 218, in request
    raise Forbidden(r, data)
discord.errors.Forbidden: 403 FORBIDDEN (error code: 50007): Cannot send messages to this user
Ignoring exception in on_message
Traceback (most recent call last):
  File "/home/bobwithacamera/.local/lib/python3.5/site-packages/discord/client.py", line 270, in _run_event
    await coro(*args, **kwargs)
  File "bot.py", line 58, in on_message
    await message.author.send(embed=help)
  File "/home/bobwithacamera/.local/lib/python3.5/site-packages/discord/abc.py", line 823, in send
    data = await state.http.send_message(channel.id, content, tts=tts, embed=embed, nonce=nonce)
  File "/home/bobwithacamera/.local/lib/python3.5/site-packages/discord/http.py", line 218, in request
    raise Forbidden(r, data)
discord.errors.Forbidden: 403 FORBIDDEN (error code: 50007): Cannot send messages to this user
Ignoring exception in on_message
Traceback (most recent call last):
  File "/home/bobwithacamera/.local/lib/python3.5/site-packages/discord/client.py", line 270, in _run_event
    await coro(*args, **kwargs)
  File "bot.py", line 58, in on_message
    await message.author.send(embed=help)
  File "/home/bobwithacamera/.local/lib/python3.5/site-packages/discord/abc.py", line 791, in send
    channel = await self._get_channel()
  File "/home/bobwithacamera/.local/lib/python3.5/site-packages/discord/user.py", line 659, in _get_channel
    ch = await self.create_dm()
  File "/home/bobwithacamera/.local/lib/python3.5/site-packages/discord/user.py", line 682, in create_dm
    data = await state.http.start_private_message(self.id)
  File "/home/bobwithacamera/.local/lib/python3.5/site-packages/discord/http.py", line 222, in request
    raise HTTPException(r, data)
discord.errors.HTTPException: 400 BAD REQUEST (error code: 50033): Invalid Recipient(s)
Ignoring exception in on_message
Traceback (most recent call last):
  File "/home/bobwithacamera/.local/lib/python3.5/site-packages/discord/client.py", line 270, in _run_event
    await coro(*args, **kwargs)
  File "bot.py", line 58, in on_message
    await message.author.send(embed=help)
  File "/home/bobwithacamera/.local/lib/python3.5/site-packages/discord/abc.py", line 791, in send
    channel = await self._get_channel()
  File "/home/bobwithacamera/.local/lib/python3.5/site-packages/discord/user.py", line 659, in _get_channel
    ch = await self.create_dm()
  File "/home/bobwithacamera/.local/lib/python3.5/site-packages/discord/user.py", line 682, in create_dm
    data = await state.http.start_private_message(self.id)
  File "/home/bobwithacamera/.local/lib/python3.5/site-packages/discord/http.py", line 222, in request
    raise HTTPException(r, data)
discord.errors.HTTPException: 400 BAD REQUEST (error code: 50033): Invalid Recipient(s)
Ignoring exception in on_message
Traceback (most recent call last):
  File "/home/bobwithacamera/.local/lib/python3.5/site-packages/discord/client.py", line 270, in _run_event
    await coro(*args, **kwargs)
  File "bot.py", line 58, in on_message
    await message.author.send(embed=help)
  File "/home/bobwithacamera/.local/lib/python3.5/site-packages/discord/abc.py", line 823, in send
    data = await state.http.send_message(channel.id, content, tts=tts, embed=embed, nonce=nonce)
  File "/home/bobwithacamera/.local/lib/python3.5/site-packages/discord/http.py", line 218, in request
    raise Forbidden(r, data)
discord.errors.Forbidden: 403 FORBIDDEN (error code: 50007): Cannot send messages to this user
Ignoring exception in on_message
Traceback (most recent call last):
  File "/home/bobwithacamera/.local/lib/python3.5/site-packages/discord/client.py", line 270, in _run_event
    await coro(*args, **kwargs)
  File "bot.py", line 58, in on_message
    await message.author.send(embed=help)
  File "/home/bobwithacamera/.local/lib/python3.5/site-packages/discord/abc.py", line 823, in send
    data = await state.http.send_message(channel.id, content, tts=tts, embed=embed, nonce=nonce)
  File "/home/bobwithacamera/.local/lib/python3.5/site-packages/discord/http.py", line 218, in request
    raise Forbidden(r, data)
discord.errors.Forbidden: 403 FORBIDDEN (error code: 50007): Cannot send messages to this user
Ignoring exception in on_message
Traceback (most recent call last):
  File "/home/bobwithacamera/.local/lib/python3.5/site-packages/discord/client.py", line 270, in _run_event
    await coro(*args, **kwargs)
  File "bot.py", line 58, in on_message
    await message.author.send(embed=help)
  File "/home/bobwithacamera/.local/lib/python3.5/site-packages/discord/abc.py", line 823, in send
    data = await state.http.send_message(channel.id, content, tts=tts, embed=embed, nonce=nonce)
  File "/home/bobwithacamera/.local/lib/python3.5/site-packages/discord/http.py", line 218, in request
    raise Forbidden(r, data)
discord.errors.Forbidden: 403 FORBIDDEN (error code: 50007): Cannot send messages to this user
Ignoring exception in on_message
Traceback (most recent call last):
  File "/home/bobwithacamera/.local/lib/python3.5/site-packages/discord/client.py", line 270, in _run_event
    await coro(*args, **kwargs)
  File "bot.py", line 58, in on_message
    await message.author.send(embed=help)
  File "/home/bobwithacamera/.local/lib/python3.5/site-packages/discord/abc.py", line 823, in send
    data = await state.http.send_message(channel.id, content, tts=tts, embed=embed, nonce=nonce)
  File "/home/bobwithacamera/.local/lib/python3.5/site-packages/discord/http.py", line 218, in request
    raise Forbidden(r, data)
discord.errors.Forbidden: 403 FORBIDDEN (error code: 50007): Cannot send messages to this user
Ignoring exception in on_message
Traceback (most recent call last):
  File "/home/bobwithacamera/.local/lib/python3.5/site-packages/discord/client.py", line 270, in _run_event
    await coro(*args, **kwargs)
  File "bot.py", line 58, in on_message
    await message.author.send(embed=help)
  File "/home/bobwithacamera/.local/lib/python3.5/site-packages/discord/abc.py", line 823, in send
    data = await state.http.send_message(channel.id, content, tts=tts, embed=embed, nonce=nonce)
  File "/home/bobwithacamera/.local/lib/python3.5/site-packages/discord/http.py", line 218, in request
    raise Forbidden(r, data)
discord.errors.Forbidden: 403 FORBIDDEN (error code: 50007): Cannot send messages to this user
Ignoring exception in on_message
Traceback (most recent call last):
  File "/home/bobwithacamera/.local/lib/python3.5/site-packages/discord/client.py", line 270, in _run_event
    await coro(*args, **kwargs)
  File "bot.py", line 58, in on_message
    await message.author.send(embed=help)
  File "/home/bobwithacamera/.local/lib/python3.5/site-packages/discord/abc.py", line 823, in send
    data = await state.http.send_message(channel.id, content, tts=tts, embed=embed, nonce=nonce)
  File "/home/bobwithacamera/.local/lib/python3.5/site-packages/discord/http.py", line 218, in request
    raise Forbidden(r, data)
discord.errors.Forbidden: 403 FORBIDDEN (error code: 50007): Cannot send messages to this user
Ignoring exception in on_message
Traceback (most recent call last):
  File "/home/bobwithacamera/.local/lib/python3.5/site-packages/discord/client.py", line 270, in _run_event
    await coro(*args, **kwargs)
  File "bot.py", line 58, in on_message
    await message.author.send(embed=help)
  File "/home/bobwithacamera/.local/lib/python3.5/site-packages/discord/abc.py", line 823, in send
    data = await state.http.send_message(channel.id, content, tts=tts, embed=embed, nonce=nonce)
  File "/home/bobwithacamera/.local/lib/python3.5/site-packages/discord/http.py", line 218, in request
    raise Forbidden(r, data)
discord.errors.Forbidden: 403 FORBIDDEN (error code: 50007): Cannot send messages to this user
Ignoring exception in on_message
Traceback (most recent call last):
  File "/home/bobwithacamera/.local/lib/python3.5/site-packages/discord/client.py", line 270, in _run_event
    await coro(*args, **kwargs)
  File "bot.py", line 58, in on_message
    await message.author.send(embed=help)
  File "/home/bobwithacamera/.local/lib/python3.5/site-packages/discord/abc.py", line 823, in send
    data = await state.http.send_message(channel.id, content, tts=tts, embed=embed, nonce=nonce)
  File "/home/bobwithacamera/.local/lib/python3.5/site-packages/discord/http.py", line 218, in request
    raise Forbidden(r, data)
discord.errors.Forbidden: 403 FORBIDDEN (error code: 50007): Cannot send messages to this user
Ignoring exception in on_message
Traceback (most recent call last):
  File "/home/bobwithacamera/.local/lib/python3.5/site-packages/discord/client.py", line 270, in _run_event
    await coro(*args, **kwargs)
  File "bot.py", line 58, in on_message
    await message.author.send(embed=help)
  File "/home/bobwithacamera/.local/lib/python3.5/site-packages/discord/abc.py", line 823, in send
    data = await state.http.send_message(channel.id, content, tts=tts, embed=embed, nonce=nonce)
  File "/home/bobwithacamera/.local/lib/python3.5/site-packages/discord/http.py", line 218, in request
    raise Forbidden(r, data)
discord.errors.Forbidden: 403 FORBIDDEN (error code: 50007): Cannot send messages to this user
Ignoring exception in on_message
Traceback (most recent call last):
  File "/home/bobwithacamera/.local/lib/python3.5/site-packages/discord/client.py", line 270, in _run_event
    await coro(*args, **kwargs)
  File "bot.py", line 58, in on_message
    await message.author.send(embed=help)
  File "/home/bobwithacamera/.local/lib/python3.5/site-packages/discord/abc.py", line 823, in send
    data = await state.http.send_message(channel.id, content, tts=tts, embed=embed, nonce=nonce)
  File "/home/bobwithacamera/.local/lib/python3.5/site-packages/discord/http.py", line 218, in request
    raise Forbidden(r, data)
discord.errors.Forbidden: 403 FORBIDDEN (error code: 50007): Cannot send messages to this user
Ignoring exception in on_message
Traceback (most recent call last):
  File "/home/bobwithacamera/.local/lib/python3.5/site-packages/discord/client.py", line 270, in _run_event
    await coro(*args, **kwargs)
  File "bot.py", line 58, in on_message
    await message.author.send(embed=help)
  File "/home/bobwithacamera/.local/lib/python3.5/site-packages/discord/abc.py", line 823, in send
    data = await state.http.send_message(channel.id, content, tts=tts, embed=embed, nonce=nonce)
  File "/home/bobwithacamera/.local/lib/python3.5/site-packages/discord/http.py", line 218, in request
    raise Forbidden(r, data)
discord.errors.Forbidden: 403 FORBIDDEN (error code: 50007): Cannot send messages to this user
Ignoring exception in on_message
Traceback (most recent call last):
  File "/home/bobwithacamera/.local/lib/python3.5/site-packages/discord/client.py", line 270, in _run_event
    await coro(*args, **kwargs)
  File "bot.py", line 58, in on_message
    await message.author.send(embed=help)
  File "/home/bobwithacamera/.local/lib/python3.5/site-packages/discord/abc.py", line 823, in send
    data = await state.http.send_message(channel.id, content, tts=tts, embed=embed, nonce=nonce)
  File "/home/bobwithacamera/.local/lib/python3.5/site-packages/discord/http.py", line 218, in request
    raise Forbidden(r, data)
discord.errors.Forbidden: 403 FORBIDDEN (error code: 50007): Cannot send messages to this user
Ignoring exception in on_message
Traceback (most recent call last):
  File "/home/bobwithacamera/.local/lib/python3.5/site-packages/discord/client.py", line 270, in _run_event
    await coro(*args, **kwargs)
  File "bot.py", line 58, in on_message
    await message.author.send(embed=help)
  File "/home/bobwithacamera/.local/lib/python3.5/site-packages/discord/abc.py", line 823, in send
    data = await state.http.send_message(channel.id, content, tts=tts, embed=embed, nonce=nonce)
  File "/home/bobwithacamera/.local/lib/python3.5/site-packages/discord/http.py", line 218, in request
    raise Forbidden(r, data)
discord.errors.Forbidden: 403 FORBIDDEN (error code: 50007): Cannot send messages to this user
Ignoring exception in on_message
Traceback (most recent call last):
  File "/home/bobwithacamera/.local/lib/python3.5/site-packages/discord/client.py", line 270, in _run_event
    await coro(*args, **kwargs)
  File "bot.py", line 251, in on_message
    with open("users/" + str(message.author.id) + '.json', 'w+') as outfile:
FileNotFoundError: [Errno 2] No such file or directory: 'users/231521966228635658.json'
Ignoring exception in on_message
Traceback (most recent call last):
  File "/home/bobwithacamera/.local/lib/python3.5/site-packages/discord/client.py", line 270, in _run_event
    await coro(*args, **kwargs)
  File "bot.py", line 251, in on_message
    with open("users/" + str(message.author.id) + '.json', 'w+') as outfile:
FileNotFoundError: [Errno 2] No such file or directory: 'users/231521966228635658.json'
Ignoring exception in on_message
Traceback (most recent call last):
  File "/home/bobwithacamera/.local/lib/python3.5/site-packages/discord/client.py", line 270, in _run_event
    await coro(*args, **kwargs)
  File "bot.py", line 251, in on_message
    with open("users/" + str(message.author.id) + '.json', 'w+') as outfile:
FileNotFoundError: [Errno 2] No such file or directory: 'users/231521966228635658.json'
Ignoring exception in on_message
Traceback (most recent call last):
  File "/home/bobwithacamera/.local/lib/python3.5/site-packages/discord/client.py", line 270, in _run_event
    await coro(*args, **kwargs)
  File "bot.py", line 251, in on_message
    with open("users/" + str(message.author.id) + '.json', 'w+') as outfile:
FileNotFoundError: [Errno 2] No such file or directory: 'users/231521966228635658.json'
Ignoring exception in on_message